녕하세요. 파이썬에서 이메일 API를 사용하여 메일을 보내는 함수에서 TypeError: cannot unpack non-iterable NoneType object 오류가 발생하는 경우, 이는 여러 값을 반환할 것으로 예상되는 곳(주로 튜플이나 리스트)에서 실제로는 None 값을 반환받았는데, 이를 여러 변수에 풀어서 할당하려고 할 때 발생합니다.

쉽게 말해, 코드 어딘가에서 a, b = some_function() 와 같은 형태로 값을 받으려고 하는데, some_function()이 예상과 달리 (값1, 값2) 형태가 아닌 None을 반환했다는 의미입니다.

발생 가능한 원인 및 해결 방법:

API 호출 실패 또는 예상치 못한 반환 값:

원인: 이메일 발송 API를 호출했을 때, 성공적인 응답 (예: 상태 코드와 메시지를 담은 튜플) 대신 실패를 나타내는 None이나 다른 예상치 못한 값을 반환했을 수 있습니다. 네트워크 오류, 인증 실패, 잘못된 요청 등으로 API 호출 자체가 실패했을 수도 있습니다.
해결:
API 호출 직후 반환 값을 **출력(print)**하여 실제로 어떤 값이 오는지 확인하세요.
API 호출 부분을 try...except 블록으로 감싸서 예외 처리를 해주세요.
API 문서(documentation)를 다시 확인하여, 실패 시 어떤 값을 반환하는지, 또는 예외를 발생시키는지 확인하고 그에 맞게 코드를 수정하세요.
Python

# 예시: API 호출 결과 확인 및 처리
api_response = call_email_api(recipient, subject, body)

print(f"API 응답: {api_response}") # <-- 응답 값 확인!

if api_response is not None:
    # API가 성공적으로 (status, message) 같은 튜플을 반환한다고 가정
    try:
        status, message = api_response # 여기서 오류가 발생했을 수 있음
        print(f"메일 발송 상태: {status}, 메시지: {message}")
        # ... 성공 처리 로직 ...
    except TypeError:
        print(f"오류: API 응답을 처리할 수 없습니다. 응답 값: {api_response}")
    except ValueError:
         print(f"오류: 예상한 개수의 값이 반환되지 않았습니다. 응답 값: {api_response}")
else:
    print("오류: API 호출에 실패했거나 None을 반환했습니다.")
    # ... 실패 처리 로직 ...

# 또는 try-except 활용
try:
    status, message = call_email_api(recipient, subject, body)
    # ... 성공 로직 ...
except TypeError as e:
    # call_email_api가 None을 반환하면 여기서 TypeError 발생
    print(f"API 호출 결과 처리 중 오류 발생: {e}")
    print("API 호출이 실패했거나 예상치 못한 값을 반환했을 수 있습니다.")
    # ... 실패 처리 로직 ...
except Exception as e:
    # 네트워크 오류 등 다른 예외 처리
    print(f"API 호출 중 예외 발생: {e}")
    # ... 실패 처리 로직 ...
함수 내부 로직 오류:

원인: 메일 발송 함수 내부에서 다른 함수를 호출하거나 어떤 로직을 수행한 결과가 None이 되었고, 이 None 값을 여러 변수에 할당하려고 시도했을 수 있습니다. 예를 들어, 설정 파일에서 API 키를 읽어오는 함수가 실패하여 None을 반환했는데, 이를 api_key, secret_key = load_credentials() 처럼 받으려고 했을 수 있습니다.
해결:
오류가 발생한 정확한 코드 라인을 확인하세요 (오류 메시지의 트레이스백(traceback)을 보면 알 수 있습니다).
해당 라인에서 값을 할당받는 변수(오른쪽 항)가 어떤 함수 호출이나 연산의 결과인지 확인하고, 그 함수나 연산이 None을 반환할 가능성이 있는지 검토하세요.
필요하다면 해당 함수/연산 결과가 None인지 먼저 확인하는 조건문(if result is not None:)을 추가하세요.
Python

# 예시: 내부 함수 호출 결과 확인
def get_email_config():
    # 설정 로딩 실패 시 None 반환 가능성 있음
    # ... 설정 로딩 로직 ...
    if success:
        return ("smtp.example.com", 587)
    else:
        return None

config_result = get_email_config()
print(f"설정 로딩 결과: {config_result}") # <-- 결과 확인!

if config_result is not None:
    try:
       server, port = config_result # 여기서 오류 발생 가능
       # ... 다음 로직 ...
    except TypeError:
        print(f"오류: 설정 결과를 처리할 수 없습니다. 결과 값: {config_result}")
else:
    print("오류: 이메일 설정을 불러오지 못했습니다.")
가장 먼저 할 일:

오류 메시지 전체(Traceback) 확인: 오류 메시지는 보통 어떤 파일의 몇 번째 줄에서 오류가 발생했는지 알려줍니다. 그 부분을 정확히 파악하는 것이 중요합니다.
오류 발생 라인 확인: 해당 라인에서 = 기호 오른쪽에 있는 값이 무엇인지 확인하고, 그 값이 왜 None이 될 수 있는지 추적해보세요.