네, 이 TimeoutError는 회사 방화벽이나 보안 정책이 프로그램의 외부 인터넷 접속을 막아서 발생하는 문제입니다.

코드가 모델을 로컬 경로에서 불러오는 중에도, 일부 설정이나 파일이 완벽한지 확인하기 위해 허깅페이스(Hugging Face) 서버에 접속을 시도할 때가 있습니다. 이때 방화벽이 연결을 차단해서 서버로부터 아무런 응답을 받지 못하고 시간이 초과되어 에러가 발생하는 것입니다.

## 핵심 해결 방법
라이브러리가 절대로 인터넷에 접속하지 말고, 무조건 로컬에 다운로드한 파일만 사용하도록 강제하는 옵션을 코드에 추가하면 됩니다.

그 옵션은 바로 local_files_only=True 입니다.

## 코드 수정
모델을 불러오는 두 줄의 코드를 아래와 같이 수정해 주세요.

?? 수정 전
Python

embedding_model = SentenceTransformer(EMBEDDING_MODEL_PATH)
# ...
tokenizer = AutoTokenizer.from_pretrained(LLM_MODEL_PATH)
model = AutoModelForCausalLM.from_pretrained(LLM_MODEL_PATH).to(device)
? 수정 후
Python

# local_files_only=True 옵션을 각 로딩 함수에 추가합니다.
embedding_model = SentenceTransformer(EMBEDDING_MODEL_PATH, local_files_only=True)
# ...
tokenizer = AutoTokenizer.from_pretrained(LLM_MODEL_PATH, local_files_only=True)
model = AutoModelForCausalLM.from_pretrained(LLM_MODEL_PATH, local_files_only=True).to(device)
이 옵션을 추가하면, 프로그램은 인터넷 연결을 시도하지 않고 오직 지정된 로컬 폴더 내의 파일들만으로 모델을 로드하기 때문에 방화벽으로 인한 타임아웃 에러가 발생하지 않습니다.